Workbook

Sheet Old Master
A1: Master SKU | B1: Website SKU | C1: ASIN | D1: Flex-1 | E1: Flex-2 | F1: SS | G1: Flipkart | H1: Myntra SKU | I1: Style I'd | J1: PPF | K1: PRODUCT | L1: CATEGORY | M1: MRP | N1: 16TH TO 31ST SP | O1: New BAU 24 April | P1: May Art Event
A2: SC-ORIG-S-72x30x6 | B2: SC-ORIG-S-72x30x6 | C2: B0BB7575JC | D2: SC-ASF-ORIG-S-72x30x6 | E2: #N/A | F2: SC-A-ORIG-S-72x30x6 | G2: SC-F-ORIG-S-72x30x6 | H2: SC-M-ORIG-S-72x30x6 | I2: 32783978 | J2: FU2187448-S-PM41515-72x30 | K2: =VLOOKUP(A2,Sheet4!$A:$H,7,0) -> Original Mattress | L2: =VLOOKUP(B2,Sheet4!$A:$H,8,0) -> Mattress | M2: 9399 | N2: 7613 | O2: 8199 | P2: 7143.24
A3: SC-ORIG-S-72x36x6 | B3: SC-ORIG-S-72x36x6 | C3: B078BRGTDM | D3: SC-ASF-72x36x6 | E3: #N/A | F3: W0-WYJN-N8R9 | G3: SC72366 | H3: SC-M-ORIG-S-72x36x6 | I3: 32783812 | J3: FU1844872-S-PM41515-72x36 | K3: =VLOOKUP(A3,Sheet4!$A:$H,7,0) -> Original Mattress | L3: =VLOOKUP(B3,Sheet4!$A:$H,8,0) -> Mattress | M3: 10399 | N3: 8423 | O3: 8999 | P3: 7903.24
A4: SC-ORIG-S-75x36x6 | B4: SC-ORIG-S-75x36x6 | C4: B077Q9YRMV | D4: SC-ASF-75x36x6 | E4: #N/A | F4: HA-T4WU-6XBG | G4: SC75366 | H4: SC-M-ORIG-S-75x36x6 | I4: 32783953 | J4: FU1844872-S-PM41515-75x36 | K4: =VLOOKUP(A4,Sheet4!$A:$H,7,0) -> Original Mattress | L4: =VLOOKUP(B4,Sheet4!$A:$H,8,0) -> Mattress | M4: 10599 | N4: 8585 | O4: 9199 | P4: 8055.24
A5: SC-ORIG-S-78x36x6 | B5: SC-ORIG-S-78x36x6 | C5: B0732Y4N38 | D5: SC-ASF-78x36x6 | E5: #N/A | F5: SC198/91 | G5: SC78366 | H5: SC-M-ORIG-S-78x36x6 | I5: 32784166 | J5: FU1844872-S-PM41515-78x36 | K5: =VLOOKUP(A5,Sheet4!$A:$H,7,0) -> Original Mattress | L5: =VLOOKUP(B5,Sheet4!$A:$H,8,0) -> Mattress | M5: 10999 | N5: 8909 | O5: 9599 | P5: 8359.24
A6: SC-ORIG-S-75x42x6 | B6: SC-ORIG-S-75x42x6 | C6: B0BB74H71K | D6: SC-ASF-ORIG-S-75x42x6 | E6: #N/A | F6: SC-A-ORIG-S-75x42x6 | G6: SC75426 | H6: SC-M-ORIG-S-75x42x6 | I6: 32784038 | J6: #N/A | K6: =VLOOKUP(A6,Sheet4!$A:$H,7,0) -> Original Mattress | L6: =VLOOKUP(B6,Sheet4!$A:$H,8,0) -> Mattress | M6: 12399 | N6: 10043 | O6: 10799 | P6: 9423.24
A7: SC-ORIG-S-84x36x6 | B7: SC-ORIG-S-84x36x6 | C7: #N/A | D7: #N/A | E7: #N/A | F7: #N/A | G7: 0 | H7: #N/A | I7: #N/A | J7: #N/A | K7: Original Mattress | L7: Mattress | M7: =VLOOKUP(A7,#REF!,2,FALSE) -> #REF! | N7: =VLOOKUP(A7, Sheet2!A:M, 3, FALSE) -> #N/A | O7: #N/A | P7: #N/A
A8: SC-ORIG-S-72x30x8 | B8: SC-ORIG-S-72x30x8 | C8: B0BB72XRJ6 | D8: SC-ASF-ORIG-S-72x30x8 | E8: #N/A | F8: SC-A-ORIG-S-72x30x8 | G8: SC-F-ORIG-S-72x30x8 | H8: SC-M-ORIG-S-72x30x8 | I8: 32788739 | J8: FU1982572-S-PM41515-72x30 | K8: =VLOOKUP(A8,Sheet4!$A:$H,7,0) -> Original Mattress | L8: =VLOOKUP(B8,Sheet4!$A:$H,8,0) -> Mattress | M8: 10399 | N8: 8423 | O8: 8999 | P8: 7903.24
A9: SC-ORIG-S-72x36x8 | B9: SC-ORIG-S-72x36x8 | C9: B07PXG7NPX | D9: SC-ASF-72x36x8 | E9: #N/A | F9: SC 72x36x8 | G9: SCP72368 | H9: SC-M-ORIG-S-72x36x8 | I9: 32783902 | J9: FU1982572-S-PM41515-72x36 | K9: =VLOOKUP(A9,Sheet4!$A:$H,7,0) -> Original Mattress | L9: =VLOOKUP(B9,Sheet4!$A:$H,8,0) -> Mattress | M9: 11599 | N9: 9395 | O9: 10099 | P9: 8815.24
A10: SC-ORIG-S-75x36x8 | B10: SC-ORIG-S-75x36x8 | C10: B07NLFV79S | D10: SC-ASF-75x36x8 | E10: #N/A | F10: SC 75x36x8 | G10: SCP75368 | H10: SC-M-ORIG-S-75x36x8 | I10: 32783867 | J10: FU1982572-S-PM41515-75x36 | K10: =VLOOKUP(A10,Sheet4!$A:$H,7,0) -> Original Mattress | L10: =VLOOKUP(B10,Sheet4!$A:$H,8,0) -> Mattress | M10: 11999 | N10: 9719 | O10: 10399 | P10: 9119.24
A11: SC-ORIG-S-78x36x8 | B11: SC-ORIG-S-78x36x8 | C11: B07PYHX5P7 | D11: SC-ASF-78x36x8 | E11: #N/A | F11: SC 78x36x8 | G11: SCP78368 | H11: SC-M-ORIG-S-78x36x8 | I11: 32783928 | J11: FU1982572-S-PM41515-78x36 | K11: =VLOOKUP(A11,Sheet4!$A:$H,7,0) -> Original Mattress | L11: =VLOOKUP(B11,Sheet4!$A:$H,8,0) -> Mattress | M11: 12299 | N11: 9962 | O11: 10699 | P11: 9347.24
A12: SC-ORIG-S-84x36x8 | B12: SC-ORIG-S-84x36x8 | C12: B0FWLNLVRL | D12: SC-ASF-ORIG-S-84x36x8 | E12: #N/A | F12: 0 | G12: SC-F-ORIG-S-84x36x8 | H12: SC-M-ORIG-S-84x36x8 | I12: #N/A | J12: #N/A | K12: =VLOOKUP(A12,Sheet4!$A:$H,7,0) -> Original Mattress | L12: =VLOOKUP(B12,Sheet4!$A:$H,8,0) -> Mattress | M12: 16999 | N12: 13769 | O12: 14799 | P12: 12919.24
A13: SC-ORIG-S-72x36x10 | B13: SC-ORIG-S-72x36x10 | C13: B09BFCJDVZ | D13: SC-ASF-72x36x10 | E13: #N/A | F13: SC-A-72x36x10 | G13: SC-F-72x36x10 | H13: SC-M-ORIG-S-72x36x10 | I13: 32784050 | J13: FU1982569-S-PM41515-72x36 | K13: =VLOOKUP(A13,Sheet4!$A:$H,7,0) -> Original Mattress | L13: =VLOOKUP(B13,Sheet4!$A:$H,8,0) -> Mattress | M13: 12999 | N13: 10529 | O13: 11299 | P13: 9879.24
A14: SC-ORIG-S-75x36x10 | B14: SC-ORIG-S-75x36x10 | C14: B09BFD48NW | D14: SC-ASF-75x36x10 | E14: #N/A | F14: SC-A-75x36x10 | G14: SC-F-75x36x10 | H14: SC-M-ORIG-S-75x36x10 | I14: 32783936 | J14: FU1982569-S-PM41515-75x36 | K14: =VLOOKUP(A14,Sheet4!$A:$H,7,0) -> Original Mattress | L14: =VLOOKUP(B14,Sheet4!$A:$H,8,0) -> Mattress | M14: 13499 | N14: 10934 | O14: 11699 | P14: 10259.24
A15: SC-ORIG-S-78x36x10 | B15: SC-ORIG-S-78x36x10 | C15: B09BFC77HD | D15: SC-ASF-78x36x10 | E15: #N/A | F15: SC-A-78x36x10 | G15: SC-F-78x36x10 | H15: SC-M-ORIG-S-78x36x10 | I15: 32784121 | J15: FU1982569-S-PM41515-78x36 | K15: =VLOOKUP(A15,Sheet4!$A:$H,7,0) -> Original Mattress | L15: =VLOOKUP(B15,Sheet4!$A:$H,8,0) -> Mattress | M15: 13999 | N15: 11339 | O15: 12199 | P15: 10639.24
A16: SC-ORIG-S-84x36x10 | B16: SC-ORIG-S-84x36x10 | C16: B0FWM2HPQ5 | D16: SC-ASF-ORIG-S-84X36X10 | E16: #N/A | F16: 0 | G16: SC-F-ORIG-S-84X36X10 | H16: SC-M-ORIG-S-84x36x10 | I16: #N/A | J16: #N/A | K16: =VLOOKUP(A16,Sheet4!$A:$H,7,0) -> Original Mattress | L16: =VLOOKUP(B16,Sheet4!$A:$H,8,0) -> Mattress | M16: 17999 | N16: 14579 | O16: 15699 | P16: 13679.24
A17: SC-ORIG-S-72x30x5 | B17: SC-ORIG-S-72x30x5 | C17: B0G256TW3Q | D17: SC-ASF-ORIG-S-72x30x5 | E17: #N/A | F17: 0 | G17: SC-F-ORIG-S-72x30x5 | H17: SC-M-ORIG-S-72x30x5 | I17: #N/A | J17: #N/A | K17: =VLOOKUP(A17,Sheet4!$A:$H,7,0) -> Original Mattress | L17: =VLOOKUP(B17,Sheet4!$A:$H,8,0) -> Mattress | M17: 9019 | N17: 7305 | O17: 7799 | P17: 6854.44
A18: SC-ORIG-S-72x36x5 | B18: SC-ORIG-S-72x36x5 | C18: B0G255BCC2 | D18: SC-ASF-ORIG-S-72x36x5 | E18: #N/A | F18: 0 | G18: SC-F-ORIG-S-72x36x5 | H18: SC-M-ORIG-S-72x36x5 | I18: #N/A | J18: FU2275237-S-PM41515-72X36 | K18: =VLOOKUP(A18,Sheet4!$A:$H,7,0) -> Original Mattress | L18: =VLOOKUP(B18,Sheet4!$A:$H,8,0) -> Mattress | M18: 9989 | N18: 8091 | O18: 8699 | P18: 7591.64
A19: SC-ORIG-S-75x30x5 | B19: SC-ORIG-S-75x30x5 | C19: B0G256TCF2 | D19: SC-ASF-ORIG-S-75x30x5 | E19: #N/A | F19: 0 | G19: SC-F-ORIG-S-75x30x5 | H19: SC-M-ORIG-S-75x30x5 | I19: #N/A | J19: FU2275237-S-PM41515-75X30 | K19: =VLOOKUP(A19,Sheet4!$A:$H,7,0) -> Original Mattress | L19: =VLOOKUP(B19,Sheet4!$A:$H,8,0) -> Mattress | M19: 9299 | N19: 7532 | O19: 8099 | P19: 7067.24
A20: SC-ORIG-S-78x30x5 | B20: SC-ORIG-S-78x30x5 | C20: B0G256HLCC | D20: SC-ASF-ORIG-S-78x30x5 | E20: #N/A | F20: 0 | G20: SC-F-ORIG-S-78x30x5 | H20: SC-M-ORIG-S-78x30x5 | I20: #N/A | J20: #N/A | K20: =VLOOKUP(A20,Sheet4!$A:$H,7,0) -> Original Mattress | L20: =VLOOKUP(B20,Sheet4!$A:$H,8,0) -> Mattress | M20: 9439 | N20: 7646 | O20: 8199 | P20: 7173.64
A21: SC-ORIG-S-75x36x5 | B21: SC-ORIG-S-75x36x5 | C21: B0G25BBWF1 | D21: SC-ASF-ORIG-S-75x36x5 | E21: #N/A | F21: 0 | G21: SC-F-ORIG-S-75x36x5 | H21: SC-M-ORIG-S-75x36x5 | I21: #N/A | J21: FU2275237-S-PM41515-75X36 | K21: =VLOOKUP(A21,Sheet4!$A:$H,7,0) -> Original Mattress | L21: =VLOOKUP(B21,Sheet4!$A:$H,8,0) -> Mattress | M21: 10269 | N21: 8318 | O21: 8899 | P21: 7804.44
A22: SC-ORIG-S-78x36x5 | B22: SC-ORIG-S-78x36x5 | C22: B0G254P8PK | D22: SC-ASF-ORIG-S-78x36x5 | E22: #N/A | F22: 0 | G22: SC-F-ORIG-S-78x36x5 | H22: SC-M-ORIG-S-78x36x5 | I22: #N/A | J22: FU2275237-S-PM41515-78X36 | K22: =VLOOKUP(A22,Sheet4!$A:$H,7,0) -> Original Mattress | L22: =VLOOKUP(B22,Sheet4!$A:$H,8,0) -> Mattress | M22: 10409 | N22: 8431 | O22: 9099 | P22: 7910.84
A23: SC-ORIG-S-84x36x5 | B23: SC-ORIG-S-84x36x5 | C23: B0G254WDXW | D23: SC-ASF-ORIG-S-84x36x5 | E23: #N/A | F23: 0 | G23: SC-F-ORIG-S-84x36x5 | H23: SC-M-ORIG-S-84x36x5 | I23: #N/A | J23: #N/A | K23: =VLOOKUP(A23,Sheet4!$A:$H,7,0) -> Original Mattress | L23: =VLOOKUP(B23,Sheet4!$A:$H,8,0) -> Mattress | M23: 11099 | N23: 8990 | O23: 9699 | P23: 8435.24
A24: SC-ORIG-S-72x42x5 | B24: SC-ORIG-S-72x42x5 | C24: B0G255Q66K | D24: SC-ASF-ORIG-S-72x42x5 | E24: #N/A | F24: 0 | G24: SC-F-ORIG-S-72x42x5 | H24: SC-M-ORIG-S-72x42x5 | I24: #N/A | J24: #N/A | K24: =VLOOKUP(A24,Sheet4!$A:$H,7,0) -> Original Mattress | L24: =VLOOKUP(B24,Sheet4!$A:$H,8,0) -> Mattress | M24: 11519 | N24: 9330 | O24: 9999 | P24: 8754.44
A25: SC-ORIG-S-75x42x5 | B25: SC-ORIG-S-75x42x5 | C25: B0G253XFRF | D25: SC-ASF-ORIG-S-75x42x5 | E25: #N/A | F25: 0 | G25: SC-F-ORIG-S-75x42x5 | H25: SC-M-ORIG-S-75x42x5 | I25: #N/A | J25: #N/A | K25: =VLOOKUP(A25,Sheet4!$A:$H,7,0) -> Original Mattress | L25: =VLOOKUP(B25,Sheet4!$A:$H,8,0) -> Mattress | M25: 11799 | N25: 9557 | O25: 10299 | P25: 8967.24
A26: SC-ORIG-S-78x42x5 | B26: SC-ORIG-S-78x42x5 | C26: B0G259Y96C | D26: SC-ASF-ORIG-S-78x42x5 | E26: #N/A | F26: 0 | G26: SC-F-ORIG-S-78x42x5 | H26: SC-M-ORIG-S-78x42x5 | I26: #N/A | J26: #N/A | K26: =VLOOKUP(A26,Sheet4!$A:$H,7,0) -> Original Mattress | L26: =VLOOKUP(B26,Sheet4!$A:$H,8,0) -> Mattress | M26: 12079 | N26: 9784 | O26: 10499 | P26: 9180.04
A27: SC-ORIG-S-72x30x4 | B27: SC-ORIG-S-72x30x4 | C27: B0G71J713Y | D27: SC-ASF-ORIG-S-72x30x4 | E27: #N/A | F27: 0 | G27: SC-F-ORIG-S-72x30x4 | H27: SC-M-ORIG-S-72x30x4 | I27: #N/A | J27: FU2289352-S-PM41515-72X30 | K27: =VLOOKUP(A27,Sheet4!$A:$H,7,0) -> Original Mattress | L27: =VLOOKUP(B27,Sheet4!$A:$H,8,0) -> Mattress | M27: 7359 | N27: 5961 | O27: 6399 | P27: 5592.84
A28: SC-ORIG-S-75x30x4 | B28: SC-ORIG-S-75x30x4 | C28: B0G727KTGD | D28: SC-ASF-ORIG-S-75x30x4 | E28: #N/A | F28: 0 | G28: SC-F-ORIG-S-75x30x4 | H28: SC-M-ORIG-S-75x30x4 | I28: #N/A | J28: FU2289352-S-PM41515-75X30 | K28: =VLOOKUP(A28,Sheet4!$A:$H,7,0) -> Original Mattress | L28: =VLOOKUP(B28,Sheet4!$A:$H,8,0) -> Mattress | M28: 7489 | N28: 6066 | O28: 6499 | P28: 5691.64
A29: SC-ORIG-S-78x30x4 | B29: SC-ORIG-S-78x30x4 | C29: B0G719KXZT | D29: SC-ASF-ORIG-S-78x30x4 | E29: #N/A | F29: 0 | G29: SC-F-ORIG-S-78x30x4 | H29: SC-M-ORIG-S-78x30x4 | I29: #N/A | J29: #N/A | K29: =VLOOKUP(A29,Sheet4!$A:$H,7,0) -> Original Mattress | L29: =VLOOKUP(B29,Sheet4!$A:$H,8,0) -> Mattress | M29: 7889 | N29: 6390 | O29: 6899 | P29: 5995.64
A30: SC-ORIG-S-72x36x4 | B30: SC-ORIG-S-72x36x4 | C30: B0G71BGCB3 | D30: SC-ASF-ORIG-S-72x36x4 | E30: #N/A | F30: 0 | G30: SC-F-ORIG-S-72x36x4 | H30: SC-M-ORIG-S-72x36x4 | I30: #N/A | J30: FU2289352-S-PM41515-72X36 | K30: =VLOOKUP(A30,Sheet4!$A:$H,7,0) -> Original Mattress | L30: =VLOOKUP(B30,Sheet4!$A:$H,8,0) -> Mattress | M30: 7889 | N30: 6390 | O30: 6899 | P30: 5995.64
A31: SC-ORIG-S-75x36x4 | B31: SC-ORIG-S-75x36x4 | C31: B0G72BV76Z | D31: SC-ASF-ORIG-S-75x36x4 | E31: #N/A | F31: 0 | G31: SC-F-ORIG-S-75x36x4 | H31: SC-M-ORIG-S-75x36x4 | I31: #N/A | J31: FU2289352-S-PM41515-75X36 | K31: =VLOOKUP(A31,Sheet4!$A:$H,7,0) -> Original Mattress | L31: =VLOOKUP(B31,Sheet4!$A:$H,8,0) -> Mattress | M31: 8149 | N31: 6601 | O31: 7099 | P31: 6193.24
A32: SC-ORIG-S-78x36x4 | B32: SC-ORIG-S-78x36x4 | C32: B0G71TH7GF | D32: SC-ASF-ORIG-S-78x36x4 | E32: #N/A | F32: 0 | G32: SC-F-ORIG-S-78x36x4 | H32: SC-M-ORIG-S-78x36x4 | I32: #N/A | J32: FU2289352-S-PM41515-78X36 | K32: =VLOOKUP(A32,Sheet4!$A:$H,7,0) -> Original Mattress | L32: =VLOOKUP(B32,Sheet4!$A:$H,8,0) -> Mattress | M32: 8279 | N32: 6706 | O32: 7199 | P32: 6292.04
A33: SC-ORIG-S-84x36x4 | B33: SC-ORIG-S-84x36x4 | C33: B0G71SFH65 | D33: SC-ASF-ORIG-S-84x36x4 | E33: #N/A | F33: 0 | G33: SC-F-ORIG-S-84x36x4 | H33: SC-M-ORIG-S-84x36x4 | I33: #N/A | J33: #N/A | K33: =VLOOKUP(A33,Sheet4!$A:$H,7,0) -> Original Mattress | L33: =VLOOKUP(B33,Sheet4!$A:$H,8,0) -> Mattress | M33: 9199 | N33: 7451 | O33: 7999 | P33: 6991.24
A34: SC-ORIG-D-72x48x6 | B34: SC-ORIG-D-72x48x6 | C34: B077Q9YRMY | D34: SC-ASF-72x48x6 | E34: #N/A | F34: KB-OOUO-WLU6 | G34: SC72486 | H34: SC-M-ORIG-D-72x48x6 | I34: 31999090 | J34: FU1844873-S-PM41515-72x48 | K34: =VLOOKUP(A34,Sheet4!$A:$H,7,0) -> Original Mattress | L34: =VLOOKUP(B34,Sheet4!$A:$H,8,0) -> Mattress | M34: 12799 | N34: 10367 | O34: 11099 | P34: 9727.24
A35: SC-ORIG-D-75x48x6 | B35: SC-ORIG-D-75x48x6 | C35: B077Q8RLCP | D35: SC-ASF-75x48x6 | E35: #N/A | F35: ZF-E2HP-QL1S | G35: SC75486 | H35: SC-M-ORIG-D-75x48x6 | I35: 32783919 | J35: FU1844873-S-PM41515-75x48 | K35: =VLOOKUP(A35,Sheet4!$A:$H,7,0) -> Original Mattress | L35: =VLOOKUP(B35,Sheet4!$A:$H,8,0) -> Mattress | M35: 12999 | N35: 10529 | O35: 11299 | P35: 9879.24
A36: SC-ORIG-D-78x48x6 | B36: SC-ORIG-D-78x48x6 | C36: B0732W7MRK | D36: SC-ASF-78x48x6 | E36: #N/A | F36: SC198/121 | G36: SC78486 | H36: SC-M-ORIG-D-78x48x6 | I36: 32784035 | J36: FU1844873-S-PM41515-78x48 | K36: =VLOOKUP(A36,Sheet4!$A:$H,7,0) -> Original Mattress | L36: =VLOOKUP(B36,Sheet4!$A:$H,8,0) -> Mattress | M36: 13399 | N36: 10853 | O36: 11699 | P36: 10183.24
A37: SC-ORIG-D-84x48x6 | B37: SC-ORIG-D-84x48x6 | C37: B0FN9FDV3D | D37: SC-ASF-ORIG-D-84x48x6 | E37: #N/A | F37: 0 | G37: SC-F-ORIG-D-84x48x6 | H37: SC-M-ORIG-D-84x48x6 | I37: #N/A | J37: #REF! | K37: =VLOOKUP(A37,Sheet4!$A:$H,7,0) -> Original Mattress | L37: =VLOOKUP(B37,Sheet4!$A:$H,8,0) -> Mattress | M37: 16999 | N37: 13769 | O37: 14799 | P37: 12919.24
A38: SC-ORIG-D-72x48x8 | B38: SC-ORIG-D-72x48x8 | C38: B07PVC8NR5 | D38: SC-ASF-72x48x8 | E38: #N/A | F38: SC 72x48x8 | G38: SCP72488 | H38: SC-M-ORIG-D-72x48x8 | I38: 32783804 | J38: FU1982573-S-PM41515-72x48 | K38: =VLOOKUP(A38,Sheet4!$A:$H,7,0) -> Original Mattress | L38: =VLOOKUP(B38,Sheet4!$A:$H,8,0) -> Mattress | M38: 14499 | N38: 11744 | O38: 12599 | P38: 11019.24
A39: SC-ORIG-D-75x48x8 | B39: SC-ORIG-D-75x48x8 | C39: B07NLFVP6H | D39: SC-ASF-75x48x8 | E39: #N/A | F39: SC 75x48x8 | G39: SCP75488 | H39: SC-M-ORIG-D-75x48x8 | I39: 32784007 | J39: FU1982573-S-PM41515-75x48 | K39: =VLOOKUP(A39,Sheet4!$A:$H,7,0) -> Original Mattress | L39: =VLOOKUP(B39,Sheet4!$A:$H,8,0) -> Mattress | M39: 14899 | N39: 12068 | O39: 12999 | P39: 11323.24
A40: SC-ORIG-D-78x48x8 | B40: SC-ORIG-D-78x48x8 | C40: B07PW985JH | D40: SC-ASF-78x48x8 | E40: #N/A | F40: SC 78x48x8 | G40: SCP78488 | H40: SC-M-ORIG-D-78x48x8 | I40: 32784189 | J40: FU1982573-S-PM41515-78x48 | K40: =VLOOKUP(A40,Sheet4!$A:$H,7,0) -> Original Mattress | L40: =VLOOKUP(B40,Sheet4!$A:$H,8,0) -> Mattress | M40: 14999 | N40: 12149 | O40: 12999 | P40: 11399.24
...

Sheet New Master
A1: Master SKU | B1: Website SKU | C1: ASIN | D1: Flex-1 | E1: Flex Status | F1: Flex-2 | G1: Flex 2 Status | H1: SS | I1: SS Status | J1: Flipkart | K1: Myntra SKU | L1: Style I'd | M1: PPF | N1: PRODUCT | O1: CATEGORY | P1: MRP | Q1: 16TH TO 31ST SP | R1: New BAU 24 April | S1: May Art Event | T1: BLR | U1: MUM | V1: GGN | W1: CHN | X1: HYB | Y1: S&OP
A2: SC-CLPILW-S-27x18 | B2: SC-CLPILW-S-27x18 | C2: B08KT1QRHJ | D2: SC-A-ZIPILW-18x27 | E2: active | F2: SC-ASF-ZIPILW-18x27 | G2: active | H2: 0 | I2: 0 | J2: SC-F-CLPILW27x18 | K2: SC-M-CLPILW-S-27x18 | L2: 31629881 | M2: FU1885162-S-PM41515 | N2: Cloud Pillow | O2: Pillows | P2: 1189 | Q2: 999 | R2: 999 | S2: 949 | T2: 527 | U2: 383 | V2: 634 | W2: 342 | X2: 421 | Y2: 2307
A3: SC-LITEPILWPSET2-S-27X17 | B3: SC-LITEPILWPSET2-S-27X17 | C3: B0CV17V482 | D3: SC-A-LITEPILWPSET2-S-27X17 | E3: active | F3: #N/A | H3: SC-AS-LITEPILWPSET2-S-27X17 | I3: active | J3: SC-F-LITEPILWPSET2-S-27X17 | K3: SC-M-LITEPILWPSET2-S-27X17 | L3: 31645868 | M3: #N/A | N3: Fiber Lite | O3: Pillows | P3: 999 | Q3: 849 | R3: 849 | S3: 749 | T3: 435 | U3: 254 | V3: 106 | W3: 406 | X3: 298 | Y3: 1499
A4: SC-MFPILW-BAM-S-25x16 | B4: SC-MFPILW-BAM-S-25x16 | C4: B0822SXQGH | D4: SC-SF-MFPILW-26x16x4 | E4: active | F4: SC-ASF-MFPILW-26x16x4 | G4: active | H4: SCPWL2616 | I4: active | J4: SC-PILLOW | K4: SC-M-MFPILW-BAM-S-25x16 | L4: 31629886 | M4: FU1985094-S-PM41515 | N4: Memory Foam Pillow | O4: Pillows | P4: 1989 | Q4: 1099 | R4: 999 | S4: 949 | T4: 154 | U4: 385 | V4: 633 | W4: 2 | X4: 0 | Y4: 1174
A5: SC-SLMPILW-S-26X16 | B5: SC-SLMPILW-S-26X16 | C5: B09XBMFFZY | D5: SC-ASF-SLMPILW-S-26x16 | E5: active | F5: #N/A | H5: SC-A-SLMPILW-S-26x16 | I5: active | J5: SC-SLMPILW-S-26x16 | K5: SC-M-SLMPILW-S-26x16 | L5: 31629882 | M5: FU1985103-S-PM41515 | N5: Slim Pillow | O5: Pillows | P5: 999 | Q5: 949 | R5: 949 | S5: 899 | T5: 353 | U5: 113 | V5: 420 | W5: 2 | X5: 197 | Y5: 1085
A6: SC-PROT-Q-78x60 | B6: SC-PROT-Q-78x60 | C6: B0822WJWGS | D6: SC-ASF-P-78x60 | E6: active | F6: #N/A | H6: SCMP7860 | I6: active | J6: SC-F-PROT-Q-78x60 | K6: SC-M-PROT-Q-78x60 | L6: 31862352 | M6: #N/A | N6: Protector | O6: Bedding | P6: 989 | Q6: 940 | R6: 940 | S6: 890.1 | T6: 205 | U6: 244 | V6: 442 | W6: 0 | X6: 114 | Y6: 1005
A7: SC-DGRPILWCS-C-52x20 | B7: SC-DGRPILWCS-C-52x20 | C7: B0CWL46VZK | D7: SC-ASF-DGRPILWCS-C-52x20 | E7: active | F7: #N/A | G7: #N/A | H7: SC-DGRPILWCS-C-52x20 | I7: active | J7: SC-F-DGRPILWCS-C-52x20 | K7: SC-M-DGRPILWCS-C-52x20 | L7: #N/A | M7: #N/A | N7: Cotton Pillow Case | O7: Bedding | P7: 499 | Q7: 494.01 | R7: 499 | S7: 474.05 | T7: 45 | U7: 68 | V7: 623 | W7: 174 | X7: 70 | Y7: 980
A8: SC-BKNECKPILW-S-10x9 | B8: SC-BKNECKPILW-S-10x9 | C8: B0CJ9G9XVQ | D8: SC-ASF-BKNECKPILW-S-10x9 | E8: active | F8: #N/A | G8: #N/A | H8: SC-BKNECKPILW-S-10x9 | I8: active | J8: SC-BKNECKPILW-S-10x9 | K8: SC-M-BKNECKPILW-S-10x9 | L8: 31917204 | M8: #N/A | N8: Travel Neck Pillow | O8: Pillows | P8: 1489 | Q8: 999 | R8: 999 | S8: 949 | T8: 78 | U8: 0 | V8: 776 | W8: 0 | X8: 30 | Y8: 884
A9: SC-PROT-K-78x72 | B9: SC-PROT-K-78x72 | C9: B0822WWZRV | D9: SC-ASF-P-78x72 | E9: active | F9: #N/A | H9: SCMP7872 | I9: active | J9: SCPROK78x72 | K9: SC-M-PROT-K-78x72 | L9: 31862320 | M9: #N/A | N9: Protector | O9: Bedding | P9: 1089 | Q9: 1035 | R9: 1035 | S9: 980.1 | T9: 99 | U9: 81 | V9: 397 | W9: 0 | X9: 184 | Y9: 761
A10: SC-SBC-BL | B10: SC-SBC-BL | C10: B0FMNPTF51 | D10: SC-ASF-SBC-BL | E10: active | F10: #N/A | H10: 0 | J10: SC-FK-SBC-BL | K10: SC-M-SBC-BL | L10: #N/A | M10: #N/A | N10: Mobility | O10: Mobility | P10: 1869 | Q10: 1495 | R10: 1499 | S10: 1401.75 | T10: 64 | U10: 69 | V10: 442 | W10: 39 | X10: 60 | Y10: 674
A11: SC-SMFPILWSET1-BAM-S-22x14 | B11: SC-SMFPILWSET1-BAM-S-22x14 | C11: B0F1Y416FR | D11: SC-ASF-SMFPILWSET1-BAM-S-22x14 | E11: active | F11: #N/A | H11: SC-A-SMFPILWSET1-BAM-S-22x14 | I11: active | J11: SC-F-SMFPILWSET1-BAM-S-22x14 | K11: SC-M-SMFPILWSET1-BAM-S-22x14 | L11: #N/A | M11: #N/A | N11: Small Memory Foam Pillow | O11: Pillows | P11: 1599 | Q11: 999 | R11: 999 | S11: 959 | T11: 63 | U11: 110 | V11: 341 | W11: 2 | X11: 57 | Y11: 573
A12: SC-PBC-BL | B12: SC-PBC-BL | C12: B0FMNQ5SFR | D12: SC-ASF-PBC-BL | E12: active | F12: #N/A | H12: 0 | J12: SC-FK-PBC-BL | K12: SC-M-PBC-BL | L12: #N/A | M12: #N/A | N12: Mobility | O12: Mobility | P12: 1999 | Q12: 1599 | R12: 1599 | S12: 1499.25 | T12: 55 | U12: 51 | V12: 370 | W12: 18 | X12: 57 | Y12: 551
A13: SC-BDPILW-S-50x19 | B13: SC-BDPILW-S-50x19 | C13: 0 | D13: 0 | F13: #N/A | H13: 0 | J13: 0 | N13: Cuddle Pillow | O13: Pillows | P13: #REF! | R13: #N/A | S13: 1499 | T13: 233 | U13: 168 | V13: 0 | W13: 59 | X13: 87 | Y13: 547
A14: SC-GRCUDPILWSET-S-50x19 | B14: SC-GRCUDPILWSET-S-50x19 | C14: B08KS2YSFR | D14: SC-ASF-BDPILW-19x50 | E14: active | F14: #N/A | G14: #N/A | H14: SC-A-BDPILW-19x50 | I14: active | J14: SC-F-BDPILW19x50 | K14: SC-M-BDPILW-S-50x19 | L14: 31629884 | M14: FU1885161-S-PM41515 | N14: Cuddle Pillow | O14: Pillows | P14: 1989 | Q14: 1698 | R14: 1699 | S14: 1499 | T14: 233 | U14: 168 | V14: 0 | W14: 59 | X14: 87 | Y14: 547
A15: SC-HYBPILW-S-26X16 | B15: SC-HYBPILW-S-26X16 | C15: B09XF5SRRD | D15: SC-A-HYBPILW-S-26x16 | E15: active | F15: #N/A | G15: #N/A | H15: 0 | J15: SC-FK-HYBPILW-S-26x16 | K15: SC-M-HYBPILW-S-26x16 | L15: 31629883 | M15: FU1985091-S-PM41515 | N15: Hybrid Pillow | O15: Pillows | P15: 1999 | Q15: 1799 | R15: 1899 | S15: 1799 | T15: 81 | U15: 28 | V15: 288 | W15: 0 | X15: 50 | Y15: 447
A16: SC-PROT-Q-72x60 | B16: SC-PROT-Q-72x60 | C16: B0822X8LZY | D16: SC-ASF-P-72x60 | E16: active | F16: #N/A | H16: SCMP7260 | I16: active | J16: SC-F-PROT-Q-72x60 | K16: SC-M-PROT-Q-72x60 | L16: 31862322 | M16: #N/A | N16: Protector | O16: Bedding | P16: 989 | Q16: 940 | R16: 940 | S16: 890.1 | T16: 61 | U16: 83 | V16: 230 | W16: 0 | X16: 52 | Y16: 426
A17: SC-DCPILWSET1-BAM-25x15 | B17: SC-DCPILWSET1-BAM-25x15 | C17: B0F1937F9V | D17: SC-ASF-DCPILWSET1-BAM-25x15 | E17: active | F17: #N/A | G17: #N/A | H17: SC-A-DCPILWSET1-BAM-25x15 | I17: active | J17: SC-F-DCPILWSET1-BAM-25x15 | K17: SC-M-DCPILWSET1-BAM-25x15 | L17: 33223713 | M17: #N/A | N17: Dual Comfort Pillow | O17: Pillows | P17: 2499 | Q17: 2149 | R17: 2149 | S17: 1999 | T17: 136 | U17: 132 | V17: 94 | W17: 14 | X17: 41 | Y17: 417
A18: SC-TBLPILWCS-S-28x18 | B18: SC-TBLPILWCS-S-28x18 | C18: B0CWLCGJDC | D18: SC-FLEX-TBLPILWCS-S-28x18 | E18: active | F18: #N/A | G18: #N/A | H18: SC-TBLPILWCS-S-28x18 | I18: active | J18: SC-F-TBLPILWCS-S-28x18 | K18: SC-M-TBLPILWCS-S-28x18 | L18: #N/A | M18: #N/A | N18: Cotton Pillow Case | O18: Bedding | P18: 549 | Q18: 543.51 | R18: 549 | S18: 521.55 | T18: 284 | U18: 13 | V18: 53 | W18: 57 | X18: 5 | Y18: 412
A19: SC-PNC-BL | B19: SC-PNC-BL | C19: B0FMNTTG5B | D19: SC-ASF-PNC-BL | E19: active | F19: #N/A | H19: 0 | J19: SC-FK-PNC-BL | K19: SC-M-PNC-BL | L19: #N/A | M19: #N/A | N19: Mobility | O19: Mobility | P19: 1869 | Q19: 1495 | R19: 1499 | S19: 1401.75 | T19: 40 | U19: 50 | V19: 228 | W19: 33 | X19: 56 | Y19: 407
A20: SC-CLPILW-P-32x20 | B20: SC-CLPILW-P-32x20 | C20: B08V5B923X | D20: SC-FLEX-ZIPILW-20x32 | E20: active | F20: #N/A | G20: #N/A | H20: SC-A-ZIPILW-20x32 | I20: active | J20: SC-FK-ZIPILW-20x32 | K20: SC-M-CLPILW-P-32x20 | L20: #N/A | M20: #N/A | N20: Cloud Pillow | O20: Pillows | P20: 1489 | Q20: 1149 | R20: 1299 | S20: 999 | T20: 172 | U20: 208 | V20: 0 | W20: 20 | X20: 0 | Y20: 400
A21: SC-DGRPILWCS-S-28x18 | B21: SC-DGRPILWCS-S-28x18 | C21: B0CWL2NG34 | D21: SC-ASF-DGRPILWCS-S-28x18 | E21: active | F21: #N/A | G21: #N/A | H21: SC-DGRPILWCS-S-28x18 | I21: active | J21: SC-F-DGRPILWCS-S-28x18 | K21: SC-M-DGRPILWCS-S-28x18 | L21: #N/A | M21: #N/A | N21: Cotton Pillow Case | O21: Bedding | P21: 549 | Q21: 543.51 | R21: 549 | S21: 521.55 | T21: 142 | U21: 59 | V21: 125 | W21: 45 | X21: 15 | Y21: 386
A22: SC-LSC-BL | B22: SC-LSC-BL | C22: B0FMNM4TKZ | D22: SC-ASF-LSC-BL | E22: active | F22: #N/A | H22: 0 | J22: SC-FK-LSC-BL | K22: SC-M-LSC-M-BL | L22: #N/A | M22: #N/A | N22: Mobility | O22: Mobility | P22: 1249 | Q22: 999 | R22: 999 | S22: 936.75 | T22: 53 | U22: 56 | V22: 175 | W22: 18 | X22: 67 | Y22: 369
A23: SC-SLSTPILWCS-S-28x18 | B23: SC-SLSTPILWCS-S-28x18 | C23: B0CWKZHV5T | D23: SC-ASF-SLSTPILWCS-S-28x18 | E23: active | F23: #N/A | H23: SC-SLSTPILWCS-S-28x18 | I23: active | J23: SC-F-SLSTPILWCS-S-28x18 | K23: SC-M-SLSTPILWCS-S-28x18 | L23: #N/A | M23: #N/A | N23: Cotton Pillow Case | O23: Bedding | P23: 649 | Q23: 642.51 | R23: 649 | S23: 616.55 | T23: 36 | U23: 177 | V23: 0 | W23: 143 | X23: 0 | Y23: 356
A24: SC-OBCHPILWCS-S-28x18 | B24: SC-OBCHPILWCS-S-28x18 | C24: B0CWL313ZC | D24: SC-ASF-OBCHPILWCS-S-28x18 | E24: active | F24: #N/A | H24: SC-OBCHPILWCS-S-28x18 | I24: active | J24: SC-F-OBCHPILWCS-S-28x18 | K24: SC-M-OBCHPILWCS-S-28x18 | L24: #N/A | M24: #N/A | N24: Cotton Pillow Case | O24: Bedding | P24: 649 | Q24: 642.51 | R24: 649 | S24: 616.55 | T24: 124 | U24: 28 | V24: 110 | W24: 87 | X24: 0 | Y24: 349
A25: SC-MFPILW-CLT-S-25x16 | B25: SC-MFPILW-CLT-S-25x16 | C25: B09XF967YW | D25: SC-ASF-MFPILW-CLT-S-25x16 | E25: active | F25: #N/A | H25: SC-A-MFPILW-CLT-S-25x16 | I25: active | J25: SC-MFPILW-CLT-S-25x16 | K25: SC-M-MFPILW-CLT-S-25x16 | L25: 31629885 | M25: FU1985097-S-PM41515 | N25: CoolTEC MF Pillow | O25: Pillows | P25: 2989 | Q25: 2299 | R25: 2299 | S25: 2199 | T25: 40 | U25: 0 | V25: 261 | W25: 12 | X25: 21 | Y25: 334
A26: SC-MFPILW-BAM-C-25x16 | B26: SC-MFPILW-BAM-C-25x16 | C26: B09XFF5LPL | D26: SC-ASF-CONMFPILW-BAM-25x16 | E26: active | F26: #N/A | H26: SC-A-CONMFPILW-BAM-25x16 | I26: active | J26: SC-MFPILW-BAM-C-25x16 | K26: SC-M-MFPILW-BAM-C-25x16 | L26: 32777659 | M26: FU1985087-S-PM41515 | N26: Contour Bamboo MF Pillow | O26: Pillows | P26: 1989 | Q26: 999 | R26: 999 | S26: 999 | T26: 86 | U26: 66 | V26: 178 | W26: 0 | X26: 0 | Y26: 330
A27: SC-SBC-BLACK | B27: SC-SBC-BLACK | C27: B0GLGFVZCW | D27: SC-ASF-SBC-BLACK | E27: active | F27: #N/A | H27: 0 | J27: SC-FK-SBC-BLACK | K27: SC-M-SBC-BLACK | L27: #N/A | M27: #N/A | N27: Mobility | O27: Mobility | P27: 1869 | Q27: 1495 | R27: 1499 | S27: 1401.75 | T27: 5 | U27: 0 | V27: 315 | W27: 9 | X27: 0 | Y27: 329
A28: SC-SUPRSOFTPILW-S-25x16 | B28: SC-SUPRSOFTPILW-S-25x16 | C28: B0CRHS55FC | D28: SC-ASF-SUPRSOFTPILW-S-25x16 | E28: active | F28: #N/A | H28: SC-A-SUPRSOFTPILW-S-25x16 | I28: active | J28: SC-F-SUPRSOFTPILW-S-25x16 | K28: SC-M-SUPRSOFTPILW-S-25x16 | L28: 31629880 | M28: #N/A | N28: Marshmallow Pillow | O28: Pillows | P28: 1989 | Q28: 1699 | R28: 1699 | S28: 1599 | T28: 152 | U28: 62 | V28: 90 | W28: 24 | X28: 0 | Y28: 328
A29: SC-PSC-BLACK | B29: SC-PSC-BLACK | C29: B0GLGLF2HK | D29: SC-ASF-PSC-BLACK | E29: active | F29: #N/A | H29: 0 | J29: SC-FK-PSC-BLACK | K29: SC-M-PSC-M-BLACK | L29: #N/A | M29: #N/A | N29: Mobility | O29: Mobility | P29: 2499 | Q29: 1999 | R29: 1999 | S29: 1874.25 | T29: 48 | U29: 29 | V29: 194 | W29: 13 | X29: 40 | Y29: 324
A30: SC-PSC-BL | B30: SC-PSC-BL | C30: B0FMP5Y17Y | D30: SC-ASF-PSC-BL | E30: active | F30: #N/A | H30: 0 | J30: SC-FK-PSC-BL | K30: SC-M-PSC-M-BL | L30: #N/A | M30: #N/A | N30: Mobility | O30: Mobility | P30: 2499 | Q30: 1999 | R30: 1999 | S30: 1874.25 | T30: 0 | U30: 28 | V30: 222 | W30: 21 | X30: 43 | Y30: 314
A31: SC-MBJRFTDSHEET-Q-78x60 | B31: SC-MBJRFTDSHEET-Q-78x60 | C31: B0CTTMM1S1 | D31: SC-ASF-MBJRFTDSHEET-Q-78x60 | E31: active | F31: #N/A | H31: SC-A-MBJRFTDSHEET-Q-78x60 | I31: active | J31: SC-F-MBJRFTDSHEET-Q-78x60 | K31: SC-M-MBJRFTDSHEET-Q-78x60 | L31: 31818392 | M31: #N/A | N31: Jersey Fitted Bed sheet | O31: Bedding | P31: 1989 | Q31: 1799 | R31: 1799 | S31: 1690.65 | T31: 43 | U31: 26 | V31: 90 | W31: 45 | X31: 93 | Y31: 297
A32: SC-SLMMFPILWSET1-BAM-S-25x15 | B32: SC-SLMMFPILWSET1-BAM-S-25x15 | C32: B0GVF93GX9 | D32: SC-ASF-SLMMFPILWSET1-BAM-S-25x15 | E32: active | F32: #N/A | H32: #N/A | J32: SC-F-SLMMFPILWSET1-BAM-S-25x15 | K32: SC-M-SLMMFPILWSET1-BAM-S-25x15 | L32: #N/A | M32: #N/A | N32: Slim Pillow | O32: Pillows | P32: 1489 | Q32: 1414 | R32: 1414 | S32: 1299 | T32: 107 | U32: 83 | V32: 54 | W32: 27 | X32: 23 | Y32: 294
A33: SC-PKCOMF-D-90x100 | B33: SC-PKCOMF-D-90x100 | C33: B09BYWZCXM | D33: SC-ASF-PKCOMF-D-90x100 | E33: active | F33: #N/A | H33: SC-A-PKCOMF-D-90x100 | I33: active | J33: SC-F-PKCOMF-D-90x100 | K33: SC-M-PKCOMF-D-90x100 | L33: 31745301 | M33: FU1951905-S-PM41515 | N33: Reversible Comforter | O33: Bedding | P33: 2489 | Q33: 2098 | R33: 2099 | S33: 1999 | T33: 29 | U33: 27 | V33: 230 | W33: 0 | X33: 0 | Y33: 286
A34: SC-SLSTDVTCOVER-S-90x60 | B34: SC-SLSTDVTCOVER-S-90x60 | C34: B0CW9SHX3D | D34: SC-ASF-SLSTDVTCOVER-S-90x60 | E34: active | F34: #N/A | H34: SC-A-SLSTDVTCOVER-S-90x60 | I34: active | J34: SC-F-SLSTDVTCOVER-S-90x60 | K34: SC-M-SLSTDVTCOVER-S-90x60 | L34: #N/A | M34: #N/A | N34: Cotton Duvet cover | O34: Bedding | P34: 2089 | Q34: 1899 | R34: 1899 | S34: 1671.2 | T34: 78 | U34: 45 | V34: 87 | W34: 43 | X34: 30 | Y34: 283
A35: SC-PRPNPILWCS-S-28x18 | B35: SC-PRPNPILWCS-S-28x18 | C35: B0CWL52SCG | D35: SC-ASF-PRPNPILWCS-S-28x18 | E35: active | F35: #N/A | H35: SC-PRPNPILWCS-S-28x18 | I35: active | J35: SC-F-PRPNPILWCS-S-28x18 | K35: SC-M-PRPNPILWCS-S-28x18 | L35: #N/A | M35: #N/A | N35: Cotton Pillow Case | O35: Bedding | P35: 549 | Q35: 543.51 | R35: 549 | S35: 521.55 | T35: 21 | U35: 176 | V35: 26 | W35: 45 | X35: 0 | Y35: 268
A36: SC-PBC-BLACK | B36: SC-PBC-BLACK | C36: B0GLG771PX | D36: SC-ASF-PBC-BLACK | E36: active | F36: #N/A | H36: 0 | J36: SC-FK-PBC-BLACK | K36: SC-M-PBC-BLACK | L36: #N/A | M36: #N/A | N36: Mobility | O36: Mobility | P36: 1999 | Q36: 1599 | R36: 1599 | S36: 1499.25 | T36: 43 | U36: 18 | V36: 174 | W36: 16 | X36: 14 | Y36: 265
A37: SC-PROT-K-75x72 | B37: SC-PROT-K-75x72 | C37: B0822W6ZCG | D37: SC-ASF-P-75x72 | E37: active | F37: #N/A | H37: SCMP7572 | I37: active | J37: SC-F-PROT-K-75x72 | K37: SC-M-PROT-K-75x72 | L37: 31862314 | M37: #N/A | N37: Protector | O37: Bedding | P37: 1089 | Q37: 1035 | R37: 1035 | S37: 980.1 | T37: 19 | U37: 11 | V37: 130 | W37: 0 | X37: 95 | Y37: 255
A38: SC-STDMFTDSHEET-Q-78x60 | B38: SC-STDMFTDSHEET-Q-78x60 | C38: B0DDCGMXH2 | D38: SC-ASF-STDMFTDSHEET-Q-78x60 | E38: active | F38: #N/A | H38: SC-A-STDMFTDSHEET-Q-78x60 | I38: active | J38: SC-F-STDMFTDSHEET-Q-78x60 | K38: SC-M-STDMFTDSHEET-Q-78x60 | L38: 31818410 | M38: #N/A | N38: Sateen Fitted Sheets | O38: Bedding | P38: 2649 | Q38: 2164 | R38: 2199 | S38: 2119.2 | T38: 26 | U38: 42 | V38: 76 | W38: 44 | X38: 53 | Y38: 241
A39: SC-TBLDVTCOVER-S-90x60 | B39: SC-TBLDVTCOVER-S-90x60 | C39: B0CW9SGV8H | D39: SC-ASF-TBLDVTCOVER-S-90x60 | E39: active | F39: #N/A | H39: SC-A-TBLDVTCOVER-S-90x60 | I39: active | J39: SC-F-TBLDVTCOVER-S-90x60 | K39: SC-M-TBLDVTCOVER-S-90x60 | L39: #N/A | M39: #N/A | N39: Cotton Duvet cover | O39: Bedding | P39: 2089 | Q39: 1627 | R39: 1899 | S39: 1671.2 | T39: 56 | U39: 27 | V39: 96 | W39: 27 | X39: 31 | Y39: 237
A40: SC-CNC-BLK-SMALL | B40: SC-CNC-BLK-SMALL | C40: B0GQ3QQFJ1 | D40: SC-ASF-CNC-BLK-SMALL | E40: active | F40: #N/A | G40: #N/A | H40: 0 | I40: 0 | J40: 0 | K40: SC-M-CNC-BLK-SMALL | L40: #N/A | M40: #N/A | N40: Mobility | O40: Mobility | P40: 1299 | Q40: 999 | R40: 999 | S40: 974.25 | T40: 0 | U40: 0 | V40: 229 | W40: 0 | X40: 0 | Y40: 229
...

Sheet Copy of New Master
A1: Master SKU | B1: Website SKU | C1: ASIN | D1: Flex-1 | E1: Flex Status | F1: Flex-2 | G1: Flex 2 Status | H1: SS | I1: SS Status | J1: Flipkart | K1: Myntra SKU | L1: Style I'd | M1: PPF | N1: PRODUCT | O1: CATEGORY | P1: MRP | Q1: 16TH TO 31ST SP | R1: New BAU 24 April | S1: May Art Event | T1: BLR | U1: MUM | V1: GGN | W1: CHN | X1: HYB | Y1: S&OP
A2: SC-CLPILW-S-27x18 | B2: SC-CLPILW-S-27x18 | C2: B08KT1QRHJ | D2: SC-A-ZIPILW-18x27 | E2: active | F2: SC-ASF-ZIPILW-18x27 | G2: active | H2: 0 | I2: 0 | J2: SC-F-CLPILW27x18 | K2: SC-M-CLPILW-S-27x18 | L2: 31629881 | M2: FU1885162-S-PM41515 | N2: Cloud Pillow | O2: Pillows | P2: 1189 | Q2: 999 | R2: 999 | S2: 949 | T2: 527 | U2: 383 | V2: 634 | W2: 342 | X2: 421 | Y2: 2307
A3: SC-LITEPILWPSET2-S-27X17 | B3: SC-LITEPILWPSET2-S-27X17 | C3: B0CV17V482 | D3: SC-A-LITEPILWPSET2-S-27X17 | E3: active | F3: #N/A | H3: SC-AS-LITEPILWPSET2-S-27X17 | I3: active | J3: SC-F-LITEPILWPSET2-S-27X17 | K3: SC-M-LITEPILWPSET2-S-27X17 | L3: 31645868 | M3: #N/A | N3: Fiber Lite | O3: Pillows | P3: 999 | Q3: 849 | R3: 849 | S3: 749 | T3: 435 | U3: 254 | V3: 106 | W3: 406 | X3: 298 | Y3: 1499
A4: SC-MFPILW-BAM-S-25x16 | B4: SC-MFPILW-BAM-S-25x16 | C4: B0822SXQGH | D4: SC-SF-MFPILW-26x16x4 | E4: active | F4: SC-ASF-MFPILW-26x16x4 | G4: active | H4: SCPWL2616 | I4: active | J4: SC-PILLOW | K4: SC-M-MFPILW-BAM-S-25x16 | L4: 31629886 | M4: FU1985094-S-PM41515 | N4: Memory Foam Pillow | O4: Pillows | P4: 1989 | Q4: 1099 | R4: 999 | S4: 949 | T4: 154 | U4: 385 | V4: 633 | W4: 2 | X4: 0 | Y4: 1174
A5: SC-SLMPILW-S-26X16 | B5: SC-SLMPILW-S-26X16 | C5: B09XBMFFZY | D5: SC-ASF-SLMPILW-S-26x16 | E5: active | F5: #N/A | H5: SC-A-SLMPILW-S-26x16 | I5: active | J5: SC-SLMPILW-S-26x16 | K5: SC-M-SLMPILW-S-26x16 | L5: 31629882 | M5: FU1985103-S-PM41515 | N5: Slim Pillow | O5: Pillows | P5: 999 | Q5: 949 | R5: 949 | S5: 899 | T5: 353 | U5: 113 | V5: 420 | W5: 2 | X5: 197 | Y5: 1085
A6: SC-PROT-Q-78x60 | B6: SC-PROT-Q-78x60 | C6: B0822WJWGS | D6: SC-ASF-P-78x60 | E6: active | F6: #N/A | H6: SCMP7860 | I6: active | J6: SC-F-PROT-Q-78x60 | K6: SC-M-PROT-Q-78x60 | L6: 31862352 | M6: #N/A | N6: Protector | O6: Bedding | P6: 989 | Q6: 940 | R6: 940 | S6: 890.1 | T6: 205 | U6: 244 | V6: 442 | W6: 0 | X6: 114 | Y6: 1005
A7: SC-DGRPILWCS-C-52x20 | B7: SC-DGRPILWCS-C-52x20 | C7: B0CWL46VZK | D7: SC-ASF-DGRPILWCS-C-52x20 | E7: active | F7: #N/A | G7: #N/A | H7: SC-DGRPILWCS-C-52x20 | I7: active | J7: SC-F-DGRPILWCS-C-52x20 | K7: SC-M-DGRPILWCS-C-52x20 | L7: #N/A | M7: #N/A | N7: Cotton Pillow Case | O7: Bedding | P7: 499 | Q7: 494.01 | R7: 499 | S7: 474.05 | T7: 45 | U7: 68 | V7: 623 | W7: 174 | X7: 70 | Y7: 980
A8: SC-BKNECKPILW-S-10x9 | B8: SC-BKNECKPILW-S-10x9 | C8: B0CJ9G9XVQ | D8: SC-ASF-BKNECKPILW-S-10x9 | E8: active | F8: #N/A | G8: #N/A | H8: SC-BKNECKPILW-S-10x9 | I8: active | J8: SC-BKNECKPILW-S-10x9 | K8: SC-M-BKNECKPILW-S-10x9 | L8: 31917204 | M8: #N/A | N8: Travel Neck Pillow | O8: Pillows | P8: 1489 | Q8: 999 | R8: 999 | S8: 949 | T8: 78 | U8: 0 | V8: 776 | W8: 0 | X8: 30 | Y8: 884
A9: SC-PROT-K-78x72 | B9: SC-PROT-K-78x72 | C9: B0822WWZRV | D9: SC-ASF-P-78x72 | E9: active | F9: #N/A | H9: SCMP7872 | I9: active | J9: SCPROK78x72 | K9: SC-M-PROT-K-78x72 | L9: 31862320 | M9: #N/A | N9: Protector | O9: Bedding | P9: 1089 | Q9: 1035 | R9: 1035 | S9: 980.1 | T9: 99 | U9: 81 | V9: 397 | W9: 0 | X9: 184 | Y9: 761
A10: SC-SBC-BL | B10: SC-SBC-BL | C10: B0FMNPTF51 | D10: SC-ASF-SBC-BL | E10: active | F10: #N/A | H10: 0 | J10: SC-FK-SBC-BL | K10: SC-M-SBC-BL | L10: #N/A | M10: #N/A | N10: Mobility | O10: Mobility | P10: 1869 | Q10: 1495 | R10: 1499 | S10: 1401.75 | T10: 64 | U10: 69 | V10: 442 | W10: 39 | X10: 60 | Y10: 674
A11: SC-SMFPILWSET1-BAM-S-22x14 | B11: SC-SMFPILWSET1-BAM-S-22x14 | C11: B0F1Y416FR | D11: SC-ASF-SMFPILWSET1-BAM-S-22x14 | E11: active | F11: #N/A | H11: SC-A-SMFPILWSET1-BAM-S-22x14 | I11: active | J11: SC-F-SMFPILWSET1-BAM-S-22x14 | K11: SC-M-SMFPILWSET1-BAM-S-22x14 | L11: #N/A | M11: #N/A | N11: Small Memory Foam Pillow | O11: Pillows | P11: 1599 | Q11: 999 | R11: 999 | S11: 959 | T11: 63 | U11: 110 | V11: 341 | W11: 2 | X11: 57 | Y11: 573
A12: SC-PBC-BL | B12: SC-PBC-BL | C12: B0FMNQ5SFR | D12: SC-ASF-PBC-BL | E12: active | F12: #N/A | H12: 0 | J12: SC-FK-PBC-BL | K12: SC-M-PBC-BL | L12: #N/A | M12: #N/A | N12: Mobility | O12: Mobility | P12: 1999 | Q12: 1599 | R12: 1599 | S12: 1499.25 | T12: 55 | U12: 51 | V12: 370 | W12: 18 | X12: 57 | Y12: 551
A13: SC-BDPILW-S-50x19 | B13: SC-BDPILW-S-50x19 | C13: 0 | D13: 0 | F13: #N/A | H13: 0 | J13: 0 | N13: Cuddle Pillow | O13: Pillows | P13: #REF! | R13: #N/A | S13: 1499 | T13: 233 | U13: 168 | V13: 0 | W13: 59 | X13: 87 | Y13: 547
A14: SC-GRCUDPILWSET-S-50x19 | B14: SC-GRCUDPILWSET-S-50x19 | C14: B08KS2YSFR | D14: SC-ASF-BDPILW-19x50 | E14: active | F14: #N/A | G14: #N/A | H14: SC-A-BDPILW-19x50 | I14: active | J14: SC-F-BDPILW19x50 | K14: SC-M-BDPILW-S-50x19 | L14: 31629884 | M14: FU1885161-S-PM41515 | N14: Cuddle Pillow | O14: Pillows | P14: 1989 | Q14: 1698 | R14: 1699 | S14: 1499 | T14: 233 | U14: 168 | V14: 0 | W14: 59 | X14: 87 | Y14: 547
A15: SC-HYBPILW-S-26X16 | B15: SC-HYBPILW-S-26X16 | C15: B09XF5SRRD | D15: SC-A-HYBPILW-S-26x16 | E15: active | F15: #N/A | G15: #N/A | H15: 0 | J15: SC-FK-HYBPILW-S-26x16 | K15: SC-M-HYBPILW-S-26x16 | L15: 31629883 | M15: FU1985091-S-PM41515 | N15: Hybrid Pillow | O15: Pillows | P15: 1999 | Q15: 1799 | R15: 1899 | S15: 1799 | T15: 81 | U15: 28 | V15: 288 | W15: 0 | X15: 50 | Y15: 447
A16: SC-PROT-Q-72x60 | B16: SC-PROT-Q-72x60 | C16: B0822X8LZY | D16: SC-ASF-P-72x60 | E16: active | F16: #N/A | H16: SCMP7260 | I16: active | J16: SC-F-PROT-Q-72x60 | K16: SC-M-PROT-Q-72x60 | L16: 31862322 | M16: #N/A | N16: Protector | O16: Bedding | P16: 989 | Q16: 940 | R16: 940 | S16: 890.1 | T16: 61 | U16: 83 | V16: 230 | W16: 0 | X16: 52 | Y16: 426
A17: SC-DCPILWSET1-BAM-25x15 | B17: SC-DCPILWSET1-BAM-25x15 | C17: B0F1937F9V | D17: SC-ASF-DCPILWSET1-BAM-25x15 | E17: active | F17: #N/A | G17: #N/A | H17: SC-A-DCPILWSET1-BAM-25x15 | I17: active | J17: SC-F-DCPILWSET1-BAM-25x15 | K17: SC-M-DCPILWSET1-BAM-25x15 | L17: 33223713 | M17: #N/A | N17: Dual Comfort Pillow | O17: Pillows | P17: 2499 | Q17: 2149 | R17: 2149 | S17: 1999 | T17: 136 | U17: 132 | V17: 94 | W17: 14 | X17: 41 | Y17: 417
A18: SC-TBLPILWCS-S-28x18 | B18: SC-TBLPILWCS-S-28x18 | C18: B0CWLCGJDC | D18: SC-FLEX-TBLPILWCS-S-28x18 | E18: active | F18: #N/A | G18: #N/A | H18: SC-TBLPILWCS-S-28x18 | I18: active | J18: SC-F-TBLPILWCS-S-28x18 | K18: SC-M-TBLPILWCS-S-28x18 | L18: #N/A | M18: #N/A | N18: Cotton Pillow Case | O18: Bedding | P18: 549 | Q18: 543.51 | R18: 549 | S18: 521.55 | T18: 284 | U18: 13 | V18: 53 | W18: 57 | X18: 5 | Y18: 412
A19: SC-PNC-BL | B19: SC-PNC-BL | C19: B0FMNTTG5B | D19: SC-ASF-PNC-BL | E19: active | F19: #N/A | H19: 0 | J19: SC-FK-PNC-BL | K19: SC-M-PNC-BL | L19: #N/A | M19: #N/A | N19: Mobility | O19: Mobility | P19: 1869 | Q19: 1495 | R19: 1499 | S19: 1401.75 | T19: 40 | U19: 50 | V19: 228 | W19: 33 | X19: 56 | Y19: 407
A20: SC-CLPILW-P-32x20 | B20: SC-CLPILW-P-32x20 | C20: B08V5B923X | D20: SC-FLEX-ZIPILW-20x32 | E20: active | F20: #N/A | G20: #N/A | H20: SC-A-ZIPILW-20x32 | I20: active | J20: SC-FK-ZIPILW-20x32 | K20: SC-M-CLPILW-P-32x20 | L20: #N/A | M20: #N/A | N20: Cloud Pillow | O20: Pillows | P20: 1489 | Q20: 1149 | R20: 1299 | S20: 999 | T20: 172 | U20: 208 | V20: 0 | W20: 20 | X20: 0 | Y20: 400
A21: SC-DGRPILWCS-S-28x18 | B21: SC-DGRPILWCS-S-28x18 | C21: B0CWL2NG34 | D21: SC-ASF-DGRPILWCS-S-28x18 | E21: active | F21: #N/A | G21: #N/A | H21: SC-DGRPILWCS-S-28x18 | I21: active | J21: SC-F-DGRPILWCS-S-28x18 | K21: SC-M-DGRPILWCS-S-28x18 | L21: #N/A | M21: #N/A | N21: Cotton Pillow Case | O21: Bedding | P21: 549 | Q21: 543.51 | R21: 549 | S21: 521.55 | T21: 142 | U21: 59 | V21: 125 | W21: 45 | X21: 15 | Y21: 386
A22: SC-LSC-BL | B22: SC-LSC-BL | C22: B0FMNM4TKZ | D22: SC-ASF-LSC-BL | E22: active | F22: #N/A | H22: 0 | J22: SC-FK-LSC-BL | K22: SC-M-LSC-M-BL | L22: #N/A | M22: #N/A | N22: Mobility | O22: Mobility | P22: 1249 | Q22: 999 | R22: 999 | S22: 936.75 | T22: 53 | U22: 56 | V22: 175 | W22: 18 | X22: 67 | Y22: 369
A23: SC-SLSTPILWCS-S-28x18 | B23: SC-SLSTPILWCS-S-28x18 | C23: B0CWKZHV5T | D23: SC-ASF-SLSTPILWCS-S-28x18 | E23: active | F23: #N/A | H23: SC-SLSTPILWCS-S-28x18 | I23: active | J23: SC-F-SLSTPILWCS-S-28x18 | K23: SC-M-SLSTPILWCS-S-28x18 | L23: #N/A | M23: #N/A | N23: Cotton Pillow Case | O23: Bedding | P23: 649 | Q23: 642.51 | R23: 649 | S23: 616.55 | T23: 36 | U23: 177 | V23: 0 | W23: 143 | X23: 0 | Y23: 356
A24: SC-OBCHPILWCS-S-28x18 | B24: SC-OBCHPILWCS-S-28x18 | C24: B0CWL313ZC | D24: SC-ASF-OBCHPILWCS-S-28x18 | E24: active | F24: #N/A | H24: SC-OBCHPILWCS-S-28x18 | I24: active | J24: SC-F-OBCHPILWCS-S-28x18 | K24: SC-M-OBCHPILWCS-S-28x18 | L24: #N/A | M24: #N/A | N24: Cotton Pillow Case | O24: Bedding | P24: 649 | Q24: 642.51 | R24: 649 | S24: 616.55 | T24: 124 | U24: 28 | V24: 110 | W24: 87 | X24: 0 | Y24: 349
A25: SC-MFPILW-CLT-S-25x16 | B25: SC-MFPILW-CLT-S-25x16 | C25: B09XF967YW | D25: SC-ASF-MFPILW-CLT-S-25x16 | E25: active | F25: #N/A | H25: SC-A-MFPILW-CLT-S-25x16 | I25: active | J25: SC-MFPILW-CLT-S-25x16 | K25: SC-M-MFPILW-CLT-S-25x16 | L25: 31629885 | M25: FU1985097-S-PM41515 | N25: CoolTEC MF Pillow | O25: Pillows | P25: 2989 | Q25: 2299 | R25: 2299 | S25: 2199 | T25: 40 | U25: 0 | V25: 261 | W25: 12 | X25: 21 | Y25: 334
A26: SC-MFPILW-BAM-C-25x16 | B26: SC-MFPILW-BAM-C-25x16 | C26: B09XFF5LPL | D26: SC-ASF-CONMFPILW-BAM-25x16 | E26: active | F26: #N/A | H26: SC-A-CONMFPILW-BAM-25x16 | I26: active | J26: SC-MFPILW-BAM-C-25x16 | K26: SC-M-MFPILW-BAM-C-25x16 | L26: 32777659 | M26: FU1985087-S-PM41515 | N26: Contour Bamboo MF Pillow | O26: Pillows | P26: 1989 | Q26: 999 | R26: 999 | S26: 999 | T26: 86 | U26: 66 | V26: 178 | W26: 0 | X26: 0 | Y26: 330
A27: SC-SBC-BLACK | B27: SC-SBC-BLACK | C27: B0GLGFVZCW | D27: SC-ASF-SBC-BLACK | E27: active | F27: #N/A | H27: 0 | J27: SC-FK-SBC-BLACK | K27: SC-M-SBC-BLACK | L27: #N/A | M27: #N/A | N27: Mobility | O27: Mobility | P27: 1869 | Q27: 1495 | R27: 1499 | S27: 1401.75 | T27: 5 | U27: 0 | V27: 315 | W27: 9 | X27: 0 | Y27: 329
A28: SC-SUPRSOFTPILW-S-25x16 | B28: SC-SUPRSOFTPILW-S-25x16 | C28: B0CRHS55FC | D28: SC-ASF-SUPRSOFTPILW-S-25x16 | E28: active | F28: #N/A | H28: SC-A-SUPRSOFTPILW-S-25x16 | I28: active | J28: SC-F-SUPRSOFTPILW-S-25x16 | K28: SC-M-SUPRSOFTPILW-S-25x16 | L28: 31629880 | M28: #N/A | N28: Marshmallow Pillow | O28: Pillows | P28: 1989 | Q28: 1699 | R28: 1699 | S28: 1599 | T28: 152 | U28: 62 | V28: 90 | W28: 24 | X28: 0 | Y28: 328
A29: SC-PSC-BLACK | B29: SC-PSC-BLACK | C29: B0GLGLF2HK | D29: SC-ASF-PSC-BLACK | E29: active | F29: #N/A | H29: 0 | J29: SC-FK-PSC-BLACK | K29: SC-M-PSC-M-BLACK | L29: #N/A | M29: #N/A | N29: Mobility | O29: Mobility | P29: 2499 | Q29: 1999 | R29: 1999 | S29: 1874.25 | T29: 48 | U29: 29 | V29: 194 | W29: 13 | X29: 40 | Y29: 324
A30: SC-PSC-BL | B30: SC-PSC-BL | C30: B0FMP5Y17Y | D30: SC-ASF-PSC-BL | E30: active | F30: #N/A | H30: 0 | J30: SC-FK-PSC-BL | K30: SC-M-PSC-M-BL | L30: #N/A | M30: #N/A | N30: Mobility | O30: Mobility | P30: 2499 | Q30: 1999 | R30: 1999 | S30: 1874.25 | T30: 0 | U30: 28 | V30: 222 | W30: 21 | X30: 43 | Y30: 314
A31: SC-MBJRFTDSHEET-Q-78x60 | B31: SC-MBJRFTDSHEET-Q-78x60 | C31: B0CTTMM1S1 | D31: SC-ASF-MBJRFTDSHEET-Q-78x60 | E31: active | F31: #N/A | H31: SC-A-MBJRFTDSHEET-Q-78x60 | I31: active | J31: SC-F-MBJRFTDSHEET-Q-78x60 | K31: SC-M-MBJRFTDSHEET-Q-78x60 | L31: 31818392 | M31: #N/A | N31: Jersey Fitted Bed sheet | O31: Bedding | P31: 1989 | Q31: 1799 | R31: 1799 | S31: 1690.65 | T31: 43 | U31: 26 | V31: 90 | W31: 45 | X31: 93 | Y31: 297
A32: SC-SLMMFPILWSET1-BAM-S-25x15 | B32: SC-SLMMFPILWSET1-BAM-S-25x15 | C32: B0GVF93GX9 | D32: SC-ASF-SLMMFPILWSET1-BAM-S-25x15 | E32: active | F32: #N/A | H32: #N/A | J32: SC-F-SLMMFPILWSET1-BAM-S-25x15 | K32: SC-M-SLMMFPILWSET1-BAM-S-25x15 | L32: #N/A | M32: #N/A | N32: Slim Pillow | O32: Pillows | P32: 1489 | Q32: 1414 | R32: 1414 | S32: 1299 | T32: 107 | U32: 83 | V32: 54 | W32: 27 | X32: 23 | Y32: 294
A33: SC-PKCOMF-D-90x100 | B33: SC-PKCOMF-D-90x100 | C33: B09BYWZCXM | D33: SC-ASF-PKCOMF-D-90x100 | E33: active | F33: #N/A | H33: SC-A-PKCOMF-D-90x100 | I33: active | J33: SC-F-PKCOMF-D-90x100 | K33: SC-M-PKCOMF-D-90x100 | L33: 31745301 | M33: FU1951905-S-PM41515 | N33: Reversible Comforter | O33: Bedding | P33: 2489 | Q33: 2098 | R33: 2099 | S33: 1999 | T33: 29 | U33: 27 | V33: 230 | W33: 0 | X33: 0 | Y33: 286
A34: SC-SLSTDVTCOVER-S-90x60 | B34: SC-SLSTDVTCOVER-S-90x60 | C34: B0CW9SHX3D | D34: SC-ASF-SLSTDVTCOVER-S-90x60 | E34: active | F34: #N/A | H34: SC-A-SLSTDVTCOVER-S-90x60 | I34: active | J34: SC-F-SLSTDVTCOVER-S-90x60 | K34: SC-M-SLSTDVTCOVER-S-90x60 | L34: #N/A | M34: #N/A | N34: Cotton Duvet cover | O34: Bedding | P34: 2089 | Q34: 1899 | R34: 1899 | S34: 1671.2 | T34: 78 | U34: 45 | V34: 87 | W34: 43 | X34: 30 | Y34: 283
A35: SC-PRPNPILWCS-S-28x18 | B35: SC-PRPNPILWCS-S-28x18 | C35: B0CWL52SCG | D35: SC-ASF-PRPNPILWCS-S-28x18 | E35: active | F35: #N/A | H35: SC-PRPNPILWCS-S-28x18 | I35: active | J35: SC-F-PRPNPILWCS-S-28x18 | K35: SC-M-PRPNPILWCS-S-28x18 | L35: #N/A | M35: #N/A | N35: Cotton Pillow Case | O35: Bedding | P35: 549 | Q35: 543.51 | R35: 549 | S35: 521.55 | T35: 21 | U35: 176 | V35: 26 | W35: 45 | X35: 0 | Y35: 268
A36: SC-PBC-BLACK | B36: SC-PBC-BLACK | C36: B0GLG771PX | D36: SC-ASF-PBC-BLACK | E36: active | F36: #N/A | H36: 0 | J36: SC-FK-PBC-BLACK | K36: SC-M-PBC-BLACK | L36: #N/A | M36: #N/A | N36: Mobility | O36: Mobility | P36: 1999 | Q36: 1599 | R36: 1599 | S36: 1499.25 | T36: 43 | U36: 18 | V36: 174 | W36: 16 | X36: 14 | Y36: 265
A37: SC-PROT-K-75x72 | B37: SC-PROT-K-75x72 | C37: B0822W6ZCG | D37: SC-ASF-P-75x72 | E37: active | F37: #N/A | H37: SCMP7572 | I37: active | J37: SC-F-PROT-K-75x72 | K37: SC-M-PROT-K-75x72 | L37: 31862314 | M37: #N/A | N37: Protector | O37: Bedding | P37: 1089 | Q37: 1035 | R37: 1035 | S37: 980.1 | T37: 19 | U37: 11 | V37: 130 | W37: 0 | X37: 95 | Y37: 255
A38: SC-STDMFTDSHEET-Q-78x60 | B38: SC-STDMFTDSHEET-Q-78x60 | C38: B0DDCGMXH2 | D38: SC-ASF-STDMFTDSHEET-Q-78x60 | E38: active | F38: #N/A | H38: SC-A-STDMFTDSHEET-Q-78x60 | I38: active | J38: SC-F-STDMFTDSHEET-Q-78x60 | K38: SC-M-STDMFTDSHEET-Q-78x60 | L38: 31818410 | M38: #N/A | N38: Sateen Fitted Sheets | O38: Bedding | P38: 2649 | Q38: 2164 | R38: 2199 | S38: 2119.2 | T38: 26 | U38: 42 | V38: 76 | W38: 44 | X38: 53 | Y38: 241
A39: SC-TBLDVTCOVER-S-90x60 | B39: SC-TBLDVTCOVER-S-90x60 | C39: B0CW9SGV8H | D39: SC-ASF-TBLDVTCOVER-S-90x60 | E39: active | F39: #N/A | H39: SC-A-TBLDVTCOVER-S-90x60 | I39: active | J39: SC-F-TBLDVTCOVER-S-90x60 | K39: SC-M-TBLDVTCOVER-S-90x60 | L39: #N/A | M39: #N/A | N39: Cotton Duvet cover | O39: Bedding | P39: 2089 | Q39: 1627 | R39: 1899 | S39: 1671.2 | T39: 56 | U39: 27 | V39: 96 | W39: 27 | X39: 31 | Y39: 237
A40: SC-CNC-BLK-SMALL | B40: SC-CNC-BLK-SMALL | C40: B0GQ3QQFJ1 | D40: SC-ASF-CNC-BLK-SMALL | E40: active | F40: #N/A | G40: #N/A | H40: 0 | I40: 0 | J40: 0 | K40: SC-M-CNC-BLK-SMALL | L40: #N/A | M40: #N/A | N40: Mobility | O40: Mobility | P40: 1299 | Q40: 999 | R40: 999 | S40: 974.25 | T40: 0 | U40: 0 | V40: 229 | W40: 0 | X40: 0 | Y40: 229
...

Sheet Flex sheet
A1: seller-sku | B1: Master SKU | C1: asin1 | D1: product-id | E1: status | F1: fulfillment-channel | G1: Sold | H1: Inventory | I1: Event Price | J1: BAU | K1: MRP
A2: SC-FLEX-ORIG-K-75x72x6 | B2: SC-ORIG-K-75x72x6 | C2: B0732TFNYC | D2: B0732TFNYC | E2: Active | F2: AMAZON_IN | G2: 25 | H2: 61 | I2: 13831.24 | J2: 15799 | K2: 18199
A3: SC-ASF-ORIG-Q-72x60x6 | B3: SC-ORIG-Q-72x60x6 | C3: B078BNQ7M4 | D3: B078BNQ7M4 | E3: Active | F3: AMAZON_IN | G3: 29 | H3: 52 | I3: 11931.24 | J3: 13699 | K3: 15699
A4: SC-FLEX-78x72x8 | B4: SC-ORIG-K-78x72x8 | C4: B07JM7GQG4 | D4: B07JM7GQG4 | E4: Active | F4: AMAZON_IN | G4: 41 | H4: 95 | I4: 16111.24 | J4: 18399 | K4: 21199
A5: SC-FLEX-ORIG-Q-72x60x8 | B5: SC-ORIG-Q-72x60x8 | C5: B07MHZTP8Q | D5: B07MHZTP8Q | E5: Active | F5: AMAZON_IN | G5: 50 | H5: 99 | I5: 13299.24 | J5: 15199 | K5: 17499
A6: SC-FLEX-52x28x4 | B6: SC-BABY-S-52x28x4 | C6: B07Y36RJJ2 | D6: B07Y36RJJ2 | E6: Active | F6: AMAZON_IN | G6: #N/A | H6: 29 | I6: 2599.35 | J6: 2999 | K6: 3999
A7: SC-SF-MFPILW-26x16x4 | B7: SC-MFPILW-BAM-S-25x16 | C7: B0822SXQGH | D7: B0822SXQGH | E7: Active | F7: AMAZON_IN | G7: 1053 | H7: 6343 | I7: 949 | J7: 999 | K7: 1989
A8: SC-A-ZIPILW-18x27 | B8: SC-CLPILW-S-27x18 | C8: B08KT1QRHJ | D8: B08KT1QRHJ | E8: Active | F8: AMAZON_IN | G8: 329 | H8: 4050 | I8: 949 | J8: 999 | K8: 1189
A9: SC-FLEX-RDUVET-D-90x100 | B9: SC-COMF-D-90x100 | C9: B08KTCGSQW | D9: B08KTCGSQW | E9: Active | F9: AMAZON_IN | G9: 122 | H9: 140 | I9: 1999 | J9: 2099 | K9: 2489
A10: SC-A-ZIPILWS2-27x18 | B10: SC-CLPILWSET2-S-27x18 | C10: B08R7MX63N | D10: B08R7MX63N | E10: Active | F10: AMAZON_IN | G10: 938 | H10: #N/A | I10: 1799 | J10: 1899 | K10: 2199
A11: SC-FLEX-75x36x10 | B11: SC-ORIG-S-75x36x10 | C11: B09BFD48NW | D11: B09BFD48NW | E11: Inactive | F11: AMAZON_IN | G11: 1 | H11: 0 | I11: 10259.24 | J11: 11699 | K11: 13499
A12: SC-ASF-HYBPILWSET2-S-26x16 | B12: SC-HYBPILWSET2-S-26x16 | C12: B09XF52Y5P | D12: B09XF52Y5P | E12: Active | F12: AMAZON_IN | G12: 66 | H12: #N/A | I12: 3499 | J12: 3499 | K12: 3699
A13: SC-A-HYBPILW-S-26x16 | B13: SC-HYBPILW-S-26X16 | C13: B09XF5SRRD | D13: B09XF5SRRD | E13: Active | F13: AMAZON_IN | G13: 142 | H13: 703 | I13: 1799 | J13: 1899 | K13: 1999
A14: SC-FLEX1-HYB-LATEX-K-75x72x6 | B14: SC-HYB-LATEX-K-75x72x6 | C14: B09XFLVCHN | D14: B09XFLVCHN | E14: Active | F14: AMAZON_IN | G14: 11 | H14: 46 | I14: 15999.2 | J14: 17999 | K14: 19999
A15: SC-ASF-HYB-LATEX-D-72x48x6 | B15: SC-HYB-LATEX-D-72x48x6 | C15: B09XFLYZ66 | D15: B09XFLYZ66 | E15: Active | F15: AMAZON_IN | G15: 25 | H15: 14 | I15: 11119.2 | J15: 12499 | K15: 13899
A16: SC-ASF-HYB-LATEX-S-72x36x6 | B16: SC-HYB-LATEX-S-72x36x6 | C16: B09XFMX37N | D16: B09XFMX37N | E16: Active | F16: AMAZON_IN | G16: 15 | H16: 43 | I16: 9119.2 | J16: 10299 | K16: 11399
A17: SC-FLEX-HYB-LATEX-K-78x72x8 | B17: SC-HYB-LATEX-K-78x72x8 | C17: B09XGCSRXY | D17: B09XGCSRXY | E17: Active | F17: AMAZON_IN | G17: 107 | H17: 228 | I17: 19039.2 | J17: 21399 | K17: 23799
A18: SC-ASF-HYB-LATEX-S-72x36x8 | B18: SC-HYB-LATEX-S-72x36x8 | C18: B09XGCTNFC | D18: B09XGCTNFC | E18: Active | F18: AMAZON_IN | G18: 13 | H18: 21 | I18: 10319.2 | J18: 11599 | K18: 12899
A19: SC-ASF-HYB-LATEX-D-78x48x6 | B19: SC-HYB-LATEX-D-78x48x6 | C19: B09XGGGFCX | D19: B09XGGGFCX | E19: Inactive | F19: AMAZON_IN | G19: 2 | H19: 2 | I19: 11759.2 | J19: 13199 | K19: 14699
A20: SC-FLEX-HYB-LATEX-Q-75x60x6 | B20: SC-HYB-LATEX-Q-75x60x6 | C20: B09XGK6Q4L | D20: B09XGK6Q4L | E20: Active | F20: AMAZON_IN | G20: 35 | H20: 115 | I20: 13839.2 | J20: 15599 | K20: 17299
A21: SC-FLEX-ULTM-K-72x72x8 | B21: SC-ULTM-K-72x72x8 | C21: B09XGNVVYK | D21: B09XGNVVYK | E21: Active | F21: AMAZON_IN | G21: 6 | H21: 26 | I21: 20019.23 | J21: 24699 | K21: 25999
A22: SC-FLEX-ULTM-Q-78x60x10 | B22: SC-ULTM-Q-78x60x10 | C22: B09XGPJ4CK | D22: B09XGPJ4CK | E22: Active | F22: AMAZON_IN | G22: 3 | H22: 34 | I22: 20019.23 | J22: 24699 | K22: 25999
A23: SC-ASF-HYB-LATEX-Q-78x60x6 | B23: SC-HYB-LATEX-Q-78x60x6 | C23: B09XGPZKTZ | D23: B09XGPZKTZ | E23: Active | F23: AMAZON_IN | G23: 54 | H23: 64 | I23: 14239.2 | J23: 15999 | K23: 17799
A24: SC-FLEX-ORIG-D-78x48x10 | B24: SC-ORIG-D-78x48x10 | C24: B0BB7HVLKV | D24: B0BB7HVLKV | E24: Active | F24: AMAZON_IN | G24: 1 | H24: 7 | I24: 12919.24 | J24: 14799 | K24: 16999
... A38: SC-FLEX-QRMTTOPPER-S-78x36x2 | B38: SC-QRMTTOPPER-S-78x36x2 | C38: B0GGZVVW7D | D38: B0GGZVVW7D | E38: Inactive | F38: AMAZON_IN | G38: 5 | H38: 1 | I38: 3569.15 | J38: 3999 | K38: 4199
A39: SC-FLEX-48x24x4 | B39: SC-BABY-S-48x24x4 | C39: B07Y37P1T3 | D39: B07Y37P1T3 | E39: Active | F39: AMAZON_IN | G39: #N/A | H39: 244 | I39: 1949 | J39: 2199 | K39: 2999
A40: SC-FLEX-PROT-D-BL-75x48 | B40: SC-PROT-D-BL-75x48 | C40: B0FVS9RRLZ | D40: B0FVS9RRLZ | E40: Inactive | F40: AMAZON_IN | G40: 4 | H40: 26 | I40: 800.1 | J40: 845 | K40: 889
A41: SC-ASF-75x60x6 | B41: SC-ORIG-Q-75x60x6 | C41: B0732TMKP8 | D41: B0732TMKP8 | E41: Active | F41: AMAZON_IN | G41: 49 | H41: 69 | I41: 12159.24 | J41: 13899 | K41: 15999
A42: SC-ASF-ORIG-78x42x6 | B42: SC-ORIG-S-78x42x6 | C42: B0732W7MRJ | D42: B0732W7MRJ | E42: Inactive | F42: AMAZON_IN | G42: #N/A | H42: 0 | I42: 9119.24 | J42: 10399 | K42: 11999
A43: SC-ASF-78x48x6 | B43: SC-ORIG-D-78x48x6 | C43: B0732W7MRK | D43: B0732W7MRK | E43: Active | F43: AMAZON_IN | G43: 9 | H43: 23 | I43: 10183.24 | J43: 11699 | K43: 13399
A44: SC-ASF-78x60x6 | B44: SC-ORIG-Q-78x60x6 | C44: B0732WFNVL | D44: B0732WFNVL | E44: Active | F44: AMAZON_IN | G44: 88 | H44: 117 | I44: 12311.24 | J44: 14099 | K44: 16199
A45: SC-ASF-78x66x6 | B45: SC-ORIG-Q-78x66x6 | C45: B0732XD4WD | D45: B0732XD4WD | E45: Inactive | F45: AMAZON_IN | G45: 1 | H45: 0 | I45: 13831.24 | J45: 15799 | K45: 18199
A46: SC-FLEX1-ORIG-K-78x72x6 | B46: SC-ORIG-K-78x72x6 | C46: B0732Y4N37 | D46: B0732Y4N37 | E46: Active | F46: AMAZON_IN | G46: 129 | H46: 103 | I46: 13983.24 | J46: 15999 | K46: 18399
A47: SC-ASF-78x36x6 | B47: SC-ORIG-S-78x36x6 | C47: B0732Y4N38 | D47: B0732Y4N38 | E47: Active | F47: AMAZON_IN | G47: 17 | H47: 30 | I47: 8359.24 | J47: 9599 | K47: 10999
A48: SC-ASF-75x48x6 | B48: SC-ORIG-D-75x48x6 | C48: B077Q8RLCP | D48: B077Q8RLCP | E48: Active | F48: AMAZON_IN | G48: 15 | H48: 31 | I48: 9879.24 | J48: 11299 | K48: 12999
A49: SC-ASF-75x36x6 | B49: SC-ORIG-S-75x36x6 | C49: B077Q9YRMV | D49: B077Q9YRMV | E49: Active | F49: AMAZON_IN | G49: 5 | H49: 29 | I49: 8055.24 | J49: 9199 | K49: 10599
A50: SC-ASF-72x48x6 | B50: SC-ORIG-D-72x48x6 | C50: B077Q9YRMY | D50: B077Q9YRMY | E50: Active | F50: AMAZON_IN | G50: 45 | H50: 83 | I50: 9727.24 | J50: 11099 | K50: 12799
A51: SC-ASF-72x66x6 | B51: SC-ORIG-Q-72x66x6 | C51: B077QB4R3Y | D51: B077QB4R3Y | E51: Inactive | F51: AMAZON_IN | G51: 1 | H51: 0 | I51: 13147.24 | J51: 15099 | K51: 17299
A52: SC-ASF-72x72x6 | B52: SC-ORIG-K-72x72x6 | C52: B077QJVWBR | D52: B077QJVWBR | E52: Active | F52: AMAZON_IN | G52: 61 | H52: 82 | I52: 13679.24 | J52: 15699 | K52: 17999
A53: ASF-O1-ZZYY-NY6L | B53: SC-ORIG-S-72x42x6 | C53: B077QJVWPB | D53: B077QJVWPB | E53: Inactive | F53: AMAZON_IN | G53: #N/A | H53: #N/A | I53: 9119.24 | J53: 10399 | K53: 11999
...

Sheet Sheet4
A1: MASTER SKU | B1: width | C1: fallback Sku for price | D1: FLEX SKU | E1: SS SKU | F1: FK FSN | G1: Product | H1: CATEGORY | I1: MRP | J1: EVENT | K1: EVENT SP | L1: BAU | M1: BAU SP | N1: 16TH TO 31ST DIS | O1: 16TH TO 31ST SP | P1: Disc_level2 | Q1: Prices_level2 | S1: Price Increase | T1: DW% | U1: OLD COGS | V1: OLD NET | W1: OLD GM | X1: OLD GM% | Y1: NEW COGS | Z1: NEW NET | AA1: NEW GM | AB1: NEW GM% | AC1: Inches | AD1: COGS Increase | AG1: Event Disc% | AH1: Event Pricing | AI1: Event GM | AJ1: Event GM% | AL1: New BAU2 Disc% | AM1: New BAU2 Discount | AN1: New BAU2 Pricing
A2: SC-ULTM-LATEX-K-78x72x8 | B2: =VALUE(MID(A2, FIND("x",A2,10)+1, FIND("x",A2,FIND("x",A2,10)+1)-FIND("x",A2,10)-1)) -> 72 | C2: =SUBSTITUTE(A2, "x"&TEXT(B2,"0")&"x", "x"&TEXT(B2+2,"0")&"x") -> SC-ULTM-LATEX-K-78x74x8 | D2: SC-ASF-ULTM-LATEX-K-78x72x8 | E2: SC-A-ULTM-LATEX-K-78x72x8 | F2: SC-F-ULTM-LATEX-K-78x72x8 | G2: Ultima Latex Mattress | H2: Mattress | I2: 34999 | J2: 0.23 | K2: =ROUND(I2-I2*J2,0) -> 26949 | L2: 0.18 | M2: =ROUND(I2-I2*L2,0) -> 28699 | N2: =1-O2/I2 -> 0.10000286 | O2: 31499 | P2: =1-Q2/I2 -> 0.10000286 | Q2: 31499 | S2: =O2/M2-1 -> 0.097564375 | T2: =iferror(vlookup(A2,COGS!B:C,2,0),0%) -> 0 | U2: =IFERROR(XLOOKUP(A2,COGS!I:I,COGS!J:J), IFERROR(XLOOKUP(C2,COGS!I:I,COGS!J:J),"")) | V2: =M2/1.18 -> 24321.186 | W2: =V2-U2 -> 24321.186 | X2: =W2/V2 -> 1 | Y2: =iferror(xlookup(A2,COGS!$I:$I,COGS!$K:$K),U2*(1+iferror(vlookup(G2,COGS!$R:$U,4,0),15%))) -> 0 | Z2: =O2/118% -> 26694.068 | AA2: =Z2-Y2 -> 26694.068 | AB2: =AA2/Z2 -> 1 | AC2: =RIGHT(A2,1) -> 8 | AD2: =Y2/U2-1 -> #DIV/0! | AG2: {=IFERROR(xlookup(G2,'Old Master'!T:T,'Old Master'!V:V),N2)} -> 0.10000286 | AH2: =I2*(1-AG2) -> 31499 | AI2: =AH2/118%-Y2 -> 26694.068 | AJ2: =AI2/(AH2/118%) -> 1 | AL2: {=iferror(if(isblank(xlookup($G2,'Old Master'!$T:$T,'Old Master'!$W:$W)),AG2,xlookup($G2,'Old Master'!$T:$T,'Old Master'!$W:$W)),AG2)} -> 0.10000286 | AM2: =(I2-AN2)/I2 -> 0.10000286 | AN2: =mround($I2*(1-AL2),100)-1 -> 31499
A3: SC-HYB-LATEX-K-78x72x8 | B3: =VALUE(MID(A3, FIND("x",A3,10)+1, FIND("x",A3,FIND("x",A3,10)+1)-FIND("x",A3,10)-1)) -> 72 | C3: =SUBSTITUTE(A3, "x"&TEXT(B3,"0")&"x", "x"&TEXT(B3+2,"0")&"x") -> SC-HYB-LATEX-K-78x74x8 | D3: SC-FLEX-HYB-LATEX-K-78x72x8 | E3: SC-A-HYB-LATEX-K-78x72x8 | F3: SC-F-HYB-LATEX-K-78x72x8 | G3: Hybrid Latex Mattress | H3: Mattress | I3: 23799 | J3: 0.25 | K3: =ROUND(I3-I3*J3,0) -> 17849 | L3: 0.2 | M3: =ROUND(I3-I3*L3,0) -> 19039 | N3: 0.16 | O3: =I3*(1-N3) -> 19991.16 | P3: 0.13 | Q3: =I3*(1-P3) -> 20705.13 | R3: =Q3/M3-1 -> 0.087511424 | S3: =O3/M3-1 -> 0.05001103 | T3: =iferror(vlookup(A3,COGS!B:C,2,0),0%) -> 0 | U3: =IFERROR(XLOOKUP(A3,COGS!I:I,COGS!J:J), IFERROR(XLOOKUP(C3,COGS!I:I,COGS!J:J),"")) | V3: =M3/1.18 -> 16134.746 | W3: =V3-U3 -> 16134.746 | X3: =W3/V3 -> 1 | Y3: =iferror(xlookup(A3,COGS!$I:$I,COGS!$K:$K),U3*(1+iferror(vlookup(G3,COGS!$R:$U,4,0),15%))) -> 0 | Z3: =O3/118% -> 16941.661 | AA3: =Z3-Y3 -> 16941.661 | AB3: =AA3/Z3 -> 1 | AC3: =RIGHT(A3,1) -> 8 | AD3: =Y3/U3-1 -> #DIV/0! | AE3: =Q3/118%-Y3 -> 17546.72 | AF3: =AE3/(Q3/1.18) -> 1 | AG3: {=IFERROR(xlookup(G3,'Old Master'!T:T,'Old Master'!V:V),N3)} -> 0.16 | AH3: =I3*(1-AG3) -> 19991.16 | AI3: =AH3/118%-Y3 -> 16941.661 | AJ3: =AI3/(AH3/118%) -> 1 | AL3: {=iferror(if(isblank(xlookup($G3,'Old Master'!$T:$T,'Old Master'!$W:$W)),AG3,xlookup($G3,'Old Master'!$T:$T,'Old Master'!$W:$W)),AG3)} -> 0.16 | AM3: =(I3-AN3)/I3 -> 0.15967057 | AN3: =mround($I3*(1-AL3),100)-1 -> 19999
A4: SC-HYB-LATEX-Q-78x60x8 | B4: =VALUE(MID(A4, FIND("x",A4,10)+1, FIND("x",A4,FIND("x",A4,10)+1)-FIND("x",A4,10)-1)) -> 60 | C4: =SUBSTITUTE(A4, "x"&TEXT(B4,"0")&"x", "x"&TEXT(B4+2,"0")&"x") -> SC-HYB-LATEX-Q-78x62x8 | D4: SC-ASF-HYB-LATEX-Q-78x60x8 | E4: SC-A-HYB-LATEX-Q-78x60x8 | F4: SC-F-HYB-LATEX-Q-78x60x8 | G4: Hybrid Latex Mattress | H4: Mattress | I4: 20199 | J4: 0.25 | K4: =ROUND(I4-I4*J4,0) -> 15149 | L4: 0.2 | M4: =ROUND(I4-I4*L4,0) -> 16159 | N4: 0.16 | O4: =I4*(1-N4) -> 16967.16 | P4: 0.13 | Q4: =I4*(1-P4) -> 17573.13 | R4: =Q4/M4-1 -> 0.08751346 | S4: =O4/M4-1 -> 0.050012996 | T4: =iferror(vlookup(A4,COGS!B:C,2,0),0%) -> 0 | U4: =IFERROR(XLOOKUP(A4,COGS!I:I,COGS!J:J), IFERROR(XLOOKUP(C4,COGS!I:I,COGS!J:J),"")) | V4: =M4/1.18 -> 13694.068 | W4: =V4-U4 -> 13694.068 | X4: =W4/V4 -> 1 | Y4: =iferror(xlookup(A4,COGS!$I:$I,COGS!$K:$K),U4*(1+iferror(vlookup(G4,COGS!$R:$U,4,0),15%))) -> 0 | Z4: =O4/118% -> 14378.949 | AA4: =Z4-Y4 -> 14378.949 | AB4: =AA4/Z4 -> 1 | AC4: =RIGHT(A4,1) -> 8 | AD4: =Y4/U4-1 -> #DIV/0! | AE4: =Q4/118%-Y4 -> 14892.483 | AF4: =AE4/(Q4/1.18) -> 1 | AG4: {=IFERROR(xlookup(G4,'Old Master'!T:T,'Old Master'!V:V),N4)} -> 0.16 | AH4: =I4*(1-AG4) -> 16967.16 | AI4: =AH4/118%-Y4 -> 14378.949 | AJ4: =AI4/(AH4/118%) -> 1 | AL4: {=iferror(if(isblank(xlookup($G4,'Old Master'!$T:$T,'Old Master'!$W:$W)),AG4,xlookup($G4,'Old Master'!$T:$T,'Old Master'!$W:$W)),AG4)} -> 0.16 | AM4: =(I4-AN4)/I4 -> 0.15842368 | AN4: =mround($I4*(1-AL4),100)-1 -> 16999
A5: SC-HYB-LATEX-K-78x72x6 | B5: =VALUE(MID(A5, FIND("x",A5,10)+1, FIND("x",A5,FIND("x",A5,10)+1)-FIND("x",A5,10)-1)) -> 72 | C5: =SUBSTITUTE(A5, "x"&TEXT(B5,"0")&"x", "x"&TEXT(B5+2,"0")&"x") -> SC-HYB-LATEX-K-78x74x6 | D5: SC-SF-HYB-LATEX-K-78x72x6 | E5: SC-A-HYB-LATEX-K-78x72x6 | F5: SC-F-HYB-LATEX-K-78x72x6 | G5: Hybrid Latex Mattress | H5: Mattress | I5: 20699 | J5: 0.25 | K5: =ROUND(I5-I5*J5,0) -> 15524 | L5: 0.2 | M5: =ROUND(I5-I5*L5,0) -> 16559 | N5: 0.16 | O5: =I5*(1-N5) -> 17387.16 | P5: 0.13 | Q5: =I5*(1-P5) -> 18008.13 | R5: =Q5/M5-1 -> 0.087513135 | S5: =O5/M5-1 -> 0.050012682 | T5: =iferror(vlookup(A5,COGS!B:C,2,0),0%) -> 0 | U5: =IFERROR(XLOOKUP(A5,COGS!I:I,COGS!J:J), IFERROR(XLOOKUP(C5,COGS!I:I,COGS!J:J),"")) | V5: =M5/1.18 -> 14033.051 | W5: =V5-U5 -> 14033.051 | X5: =W5/V5 -> 1 | Y5: =iferror(xlookup(A5,COGS!$I:$I,COGS!$K:$K),U5*(1+iferror(vlookup(G5,COGS!$R:$U,4,0),15%))) -> 0 | Z5: =O5/118% -> 14734.881 | AA5: =Z5-Y5 -> 14734.881 | AB5: =AA5/Z5 -> 1 | AC5: =RIGHT(A5,1) -> 6 | AD5: =Y5/U5-1 -> #DIV/0! | AE5: =Q5/118%-Y5 -> 15261.127 | AF5: =AE5/(Q5/1.18) -> 1 | AG5: {=IFERROR(xlookup(G5,'Old Master'!T:T,'Old Master'!V:V),N5)} -> 0.16 | AH5: =I5*(1-AG5) -> 17387.16 | AI5: =AH5/118%-Y5 -> 14734.881 | AJ5: =AI5/(AH5/118%) -> 1 | AL5: {=iferror(if(isblank(xlookup($G5,'Old Master'!$T:$T,'Old Master'!$W:$W)),AG5,xlookup($G5,'Old Master'!$T:$T,'Old Master'!$W:$W)),AG5)} -> 0.16 | AM5: =(I5-AN5)/I5 -> 0.15942799 | AN5: =mround($I5*(1-AL5),100)-1 -> 17399
